Workbook

Sheet Annually
A1: Year | B1: Deals | C1: Abandoned | D1: Possibilty
A2: 2000 | B2: 1132 | C2: 1 | D2: =C2/B2 -> 0.00088339223
A3: 2001 | B3: 854 | C3: 0 | D3: =C3/B3 -> 0
A4: 2002 | B4: 580 | C4: 0 | D4: =C4/B4 -> 0
A5: 2003 | B5: 457 | C5: 1 | D5: =C5/B5 -> 0.0021881838
A6: 2004 | B6: 644 | C6: 1 | D6: =C6/B6 -> 0.001552795
A7: 2005 | B7: 519 | C7: 3 | D7: =C7/B7 -> 0.0057803468
A8: 2006 | B8: 774 | C8: 12 | D8: =C8/B8 -> 0.015503876
A9: 2007 | B9: 1500 | C9: 28 | D9: =C9/B9 -> 0.018666667
A10: 2008 | B10: 1483 | C10: 19 | D10: =C10/B10 -> 0.012811868
A11: 2009 | B11: 1299 | C11: 45 | D11: =C11/B11 -> 0.034642032
A12: 2010 | B12: 1610 | C12: 37 | D12: =C12/B12 -> 0.022981366
A13: 2010 | B13: 1798 | C13: 46 | D13: =C13/B13 -> 0.025583982
... A18: 2016 | B18: 1153 | C18: 10 | D18: =C18/B18 -> 0.0086730269
A19: 2017 | B19: 1149 | C19: 10 | D19: =C19/B19 -> 0.0087032202
A20: 2018 | B20: =SUM(Monthly!B4:B15) -> 2378 | C20: 9 | D20: =C20/B20 -> 0.003784693
A21: 2019 | B21: =SUM(Monthly!B17:B28) -> 2215 | C21: 8 | D21: =C21/B21 -> 0.0036117381
A22: 2020 | B22: =SUM(Monthly!B30:B41) -> 2047 | C22: 3 | D22: =C22/B22 -> 0.0014655594
A23: 2021 | B23: =SUM(Monthly!B43:B54) -> 2513 | C23: 2 | D23: =C23/B23 -> 0.00079586152
A24: 2022 | B24: =SUM(Monthly!B56:B67) -> 1953 | C24: 12 | D24: =C24/B24 -> 0.0061443932
A25: 2023 | B25: =SUM(Monthly!B69:B80) -> 1274 | C25: 5 | D25: =C25/B25 -> 0.0039246468
A26: 2024 | B26: =SUM(Monthly!B82:B93) -> 1259 | C26: 2 | D26: =C26/B26 -> 0.0015885624

Sheet Monthly
A1: Year | B1: Number | C1: Value | G1: Source
C2: in bil. USD | D2: in bil. EUR | E2: in bil. GBP | F2: in bil. YEN
A3: 2018
A4: 43118 | B4: 214 | C4: =46712.9/1000 -> 46.7129 | D4: =IFERROR(__xludf.DUMMYFUNCTION("C4*IMPORTRANGE(""https://docs.google.com/spreadsheets/d/1xsp01RMmkav9iTy39Zaj_7tE9677EGlOJ14KU9TZn7I"", ""2018-2025!H25"")"),38.313453451) -> 38.313453 | E4: =IFERROR(__xludf.DUMMYFUNCTION("C4*IMPORTRANGE(""https://docs.google.com/spreadsheets/d/1xsp01RMmkav9iTy39Zaj_7tE9677EGlOJ14KU9TZn7I"", ""2018-2025!T25"")"),33.854240017) -> 33.85424 | F4: =IFERROR(__xludf.DUMMYFUNCTION("C4*IMPORTRANGE(""https://docs.google.com/spreadsheets/d/1xsp01RMmkav9iTy39Zaj_7tE9677EGlOJ14KU9TZn7I"", ""2018-2025!AC25"")"),5189.8031900000005) -> 5189.8032 | G4: Capital IQ
A5: 44975 | B5: 187 | C5: =35667.4/1000 -> 35.6674 | D5: =IFERROR(__xludf.DUMMYFUNCTION("C5*IMPORTRANGE(""https://docs.google.com/spreadsheets/d/1xsp01RMmkav9iTy39Zaj_7tE9677EGlOJ14KU9TZn7I"", ""2018-2025!H46"")"),28.893269055) -> 28.893269 | E5: =IFERROR(__xludf.DUMMYFUNCTION("C5*IMPORTRANGE(""https://docs.google.com/spreadsheets/d/1xsp01RMmkav9iTy39Zaj_7tE9677EGlOJ14KU9TZn7I"", ""2018-2025!T46"")"),25.544991879999998) -> 25.544992 | F5: =IFERROR(__xludf.DUMMYFUNCTION("C5*IMPORTRANGE(""https://docs.google.com/spreadsheets/d/1xsp01RMmkav9iTy39Zaj_7tE9677EGlOJ14KU9TZn7I"", ""2018-2025!AC46"")"),3839.9344502999998) -> 3839.9345 | G5: Capital IQ
A6: 45003 | B6: 218 | C6: =105604.7/1000 -> 105.6047 | D6: =IFERROR(__xludf.DUMMYFUNCTION("C6*IMPORTRANGE(""https://docs.google.com/spreadsheets/d/1xsp01RMmkav9iTy39Zaj_7tE9677EGlOJ14KU9TZn7I"", ""2018-2025!H69"")"),85.643299606) -> 85.6433 | E6: =IFERROR(__xludf.DUMMYFUNCTION("D6*IMPORTRANGE(""https://docs.google.com/spreadsheets/d/1xsp01RMmkav9iTy39Zaj_7tE9677EGlOJ14KU9TZn7I"", ""2018-2025!t69"")"),61.35999843571476) -> 61.359998 | F6: =IFERROR(__xludf.DUMMYFUNCTION("E6*IMPORTRANGE(""https://docs.google.com/spreadsheets/d/1xsp01RMmkav9iTy39Zaj_7tE9677EGlOJ14KU9TZn7I"", ""2018-2025!ac69"")"),6514.867153912796) -> 6514.8672 | G6: Capital IQ
A7: 45034 | B7: 182 | C7: =51710.9/1000 -> 51.7109 | D7: =IFERROR(__xludf.DUMMYFUNCTION("C7*IMPORTRANGE(""https://docs.google.com/spreadsheets/d/1xsp01RMmkav9iTy39Zaj_7tE9677EGlOJ14KU9TZn7I"", ""2018-2025!H91"")"),42.066300041000005) -> 42.0663 | E7: =IFERROR(__xludf.DUMMYFUNCTION("C7*IMPORTRANGE(""https://docs.google.com/spreadsheets/d/1xsp01RMmkav9iTy39Zaj_7tE9677EGlOJ14KU9TZn7I"", ""2018-2025!t91"")"),36.70956791) -> 36.709568 | F7: =IFERROR(__xludf.DUMMYFUNCTION("C7*IMPORTRANGE(""https://docs.google.com/spreadsheets/d/1xsp01RMmkav9iTy39Zaj_7tE9677EGlOJ14KU9TZn7I"", ""2018-2025!ac91"")"),5538.9096317) -> 5538.9096 | G7: Capital IQ
A8: 45064 | B8: 184 | C8: =58268.1/1000 -> 58.2681 | D8: =IFERROR(__xludf.DUMMYFUNCTION("C8*IMPORTRANGE(""https://docs.google.com/spreadsheets/d/1xsp01RMmkav9iTy39Zaj_7tE9677EGlOJ14KU9TZn7I"", ""2018-2025!H115"")"),49.292481876) -> 49.292482 | E8: =IFERROR(__xludf.DUMMYFUNCTION("C8*IMPORTRANGE(""https://docs.google.com/spreadsheets/d/1xsp01RMmkav9iTy39Zaj_7tE9677EGlOJ14KU9TZn7I"", ""2018-2025!t115"")"),43.086929225999995) -> 43.086929 | F8: =IFERROR(__xludf.DUMMYFUNCTION("C8*IMPORTRANGE(""https://docs.google.com/spreadsheets/d/1xsp01RMmkav9iTy39Zaj_7tE9677EGlOJ14KU9TZn7I"", ""2018-2025!ac115"")"),6387.5239263) -> 6387.5239 | G8: Capital IQ
A9: 45095 | B9: 198 | C9: =43963.4/1000 -> 43.9634 | D9: =IFERROR(__xludf.DUMMYFUNCTION("C9*IMPORTRANGE(""https://docs.google.com/spreadsheets/d/1xsp01RMmkav9iTy39Zaj_7tE9677EGlOJ14KU9TZn7I"", ""2018-2025!H137"")"),37.6766338) -> 37.676634 | E9: =IFERROR(__xludf.DUMMYFUNCTION("C9*IMPORTRANGE(""https://docs.google.com/spreadsheets/d/1xsp01RMmkav9iTy39Zaj_7tE9677EGlOJ14KU9TZn7I"", ""2018-2025!T137"")"),33.10883654) -> 33.108837 | F9: =IFERROR(__xludf.DUMMYFUNCTION("C9*IMPORTRANGE(""https://docs.google.com/spreadsheets/d/1xsp01RMmkav9iTy39Zaj_7tE9677EGlOJ14KU9TZn7I"", ""2018-2025!AC137"")"),4840.2384498) -> 4840.2384 | G9: Capital IQ
A10: 45125 | B10: 189 | C10: =29384.9/1000 -> 29.3849 | D10: =IFERROR(__xludf.DUMMYFUNCTION("C10*IMPORTRANGE(""https://docs.google.com/spreadsheets/d/1xsp01RMmkav9iTy39Zaj_7tE9677EGlOJ14KU9TZn7I"", ""2018-2025!H160"")"),25.160820625) -> 25.160821 | E10: =IFERROR(__xludf.DUMMYFUNCTION("D10*IMPORTRANGE(""https://docs.google.com/spreadsheets/d/1xsp01RMmkav9iTy39Zaj_7tE9677EGlOJ14KU9TZn7I"", ""2018-2025!T160"")"),19.0794502799375) -> 19.07945 | F10: =IFERROR(__xludf.DUMMYFUNCTION("E10*IMPORTRANGE(""https://docs.google.com/spreadsheets/d/1xsp01RMmkav9iTy39Zaj_7tE9677EGlOJ14KU9TZn7I"", ""2018-2025!AC160"")"),2118.2673481546412) -> 2118.2673 | G10: Capital IQ
A11: 45156 | B11: 182 | C11: =29464.5/1000 -> 29.4645 | D11: =IFERROR(__xludf.DUMMYFUNCTION("C11*IMPORTRANGE(""https://docs.google.com/spreadsheets/d/1xsp01RMmkav9iTy39Zaj_7tE9677EGlOJ14KU9TZn7I"", ""2018-2025!H184"")"),25.4514351) -> 25.451435 | E11: =IFERROR(__xludf.DUMMYFUNCTION("C11*IMPORTRANGE(""https://docs.google.com/spreadsheets/d/1xsp01RMmkav9iTy39Zaj_7tE9677EGlOJ14KU9TZn7I"", ""2018-2025!T184"")"),22.87329135) -> 22.873291 | F11: =IFERROR(__xludf.DUMMYFUNCTION("C11*IMPORTRANGE(""https://docs.google.com/spreadsheets/d/1xsp01RMmkav9iTy39Zaj_7tE9677EGlOJ14KU9TZn7I"", ""2018-2025!AC184"")"),3274.5961365000003) -> 3274.5961 | G11: Capital IQ
A12: 45187 | B12: 186 | C12: =41716.2/1000 -> 41.7162 | D12: =IFERROR(__xludf.DUMMYFUNCTION("C12*IMPORTRANGE(""https://docs.google.com/spreadsheets/d/1xsp01RMmkav9iTy39Zaj_7tE9677EGlOJ14KU9TZn7I"", ""2018-2025!H205"")"),35.850067956000004) -> 35.850068 | E12: =IFERROR(__xludf.DUMMYFUNCTION("C12*IMPORTRANGE(""https://docs.google.com/spreadsheets/d/1xsp01RMmkav9iTy39Zaj_7tE9677EGlOJ14KU9TZn7I"", ""2018-2025!T205"")"),31.902881112) -> 31.902881 | F12: =IFERROR(__xludf.DUMMYFUNCTION("C12*IMPORTRANGE(""https://docs.google.com/spreadsheets/d/1xsp01RMmkav9iTy39Zaj_7tE9677EGlOJ14KU9TZn7I"", ""2018-2025!AC205"")"),4664.7680583) -> 4664.7681 | G12: Capital IQ
A13: 45217 | B13: 202 | C13: =82409.5/1000 -> 82.4095 | D13: =IFERROR(__xludf.DUMMYFUNCTION("C13*IMPORTRANGE(""https://docs.google.com/spreadsheets/d/1xsp01RMmkav9iTy39Zaj_7tE9677EGlOJ14KU9TZn7I"", ""2018-2025!H229"")"),71.61715188) -> 71.617152 | E13: =IFERROR(__xludf.DUMMYFUNCTION("C13*IMPORTRANGE(""https://docs.google.com/spreadsheets/d/1xsp01RMmkav9iTy39Zaj_7tE9677EGlOJ14KU9TZn7I"", ""2018-2025!T229"")"),63.171002224999995) -> 63.171002 | F13: =IFERROR(__xludf.DUMMYFUNCTION("C13*IMPORTRANGE(""https://docs.google.com/spreadsheets/d/1xsp01RMmkav9iTy39Zaj_7tE9677EGlOJ14KU9TZn7I"", ""2018-2025!AC229"")"),9269.42056) -> 9269.4206 | G13: Capital IQ
A14: 45248 | B14: 215 | C14: =53825.61/1000 -> 53.82561 | D14: =IFERROR(__xludf.DUMMYFUNCTION("C14*IMPORTRANGE(""https://docs.google.com/spreadsheets/d/1xsp01RMmkav9iTy39Zaj_7tE9677EGlOJ14KU9TZn7I"", ""2018-2025!H252"")"),47.338009226699995) -> 47.338009 | E14: =IFERROR(__xludf.DUMMYFUNCTION("C14*IMPORTRANGE(""https://docs.google.com/spreadsheets/d/1xsp01RMmkav9iTy39Zaj_7tE9677EGlOJ14KU9TZn7I"", ""2018-2025!T252"")"),41.85883125675) -> 41.858831 | F14: =IFERROR(__xludf.DUMMYFUNCTION("C14*IMPORTRANGE(""https://docs.google.com/spreadsheets/d/1xsp01RMmkav9iTy39Zaj_7tE9677EGlOJ14KU9TZn7I"", ""2018-2025!AC252"")"),6103.12444107) -> 6103.1244 | G14: Capital IQ
A15: 45278 | B15: 221 | C15: =22160.5/1000 -> 22.1605 | D15: =IFERROR(__xludf.DUMMYFUNCTION("C15*IMPORTRANGE(""https://docs.google.com/spreadsheets/d/1xsp01RMmkav9iTy39Zaj_7tE9677EGlOJ14KU9TZn7I"", ""2018-2025!H273"")"),19.485506045) -> 19.485506 | E15: =IFERROR(__xludf.DUMMYFUNCTION("C15*IMPORTRANGE(""https://docs.google.com/spreadsheets/d/1xsp01RMmkav9iTy39Zaj_7tE9677EGlOJ14KU9TZn7I"", ""2018-2025!T273"")"),17.5112271) -> 17.511227 | F15: =IFERROR(__xludf.DUMMYFUNCTION("C15*IMPORTRANGE(""https://docs.google.com/spreadsheets/d/1xsp01RMmkav9iTy39Zaj_7tE9677EGlOJ14KU9TZn7I"", ""2018-2025!AC273"")"),2497.2445844999997) -> 2497.2446 | G15: Capital IQ
A16: 2019
A17: 43484 | B17: 175 | C17: =16401.5/1000 -> 16.4015 | D17: =IFERROR(__xludf.DUMMYFUNCTION("C17*IMPORTRANGE(""https://docs.google.com/spreadsheets/d/1xsp01RMmkav9iTy39Zaj_7tE9677EGlOJ14KU9TZn7I"", ""2018-2025!H298"")"),14.36607385) -> 14.366074 | E17: =IFERROR(__xludf.DUMMYFUNCTION("C17*IMPORTRANGE(""https://docs.google.com/spreadsheets/d/1xsp01RMmkav9iTy39Zaj_7tE9677EGlOJ14KU9TZn7I"", ""2018-2025!T298"")"),12.741833304999998) -> 12.741833 | F17: =IFERROR(__xludf.DUMMYFUNCTION("C17*IMPORTRANGE(""https://docs.google.com/spreadsheets/d/1xsp01RMmkav9iTy39Zaj_7tE9677EGlOJ14KU9TZn7I"", ""2018-2025!AC298"")"),1788.3703555) -> 1788.3704 | G17: Capital IQ
A18: 43515 | B18: 177 | C18: =72770.7/1000 -> 72.7707 | D18: =IFERROR(__xludf.DUMMYFUNCTION("C18*IMPORTRANGE(""https://docs.google.com/spreadsheets/d/1xsp01RMmkav9iTy39Zaj_7tE9677EGlOJ14KU9TZn7I"", ""2018-2025!H319"")"),64.15464912) -> 64.154649 | E18: =IFERROR(__xludf.DUMMYFUNCTION("C18*IMPORTRANGE(""https://docs.google.com/spreadsheets/d/1xsp01RMmkav9iTy39Zaj_7tE9677EGlOJ14KU9TZn7I"", ""2018-2025!T319"")"),56.00323915949999) -> 56.003239 | F18: =IFERROR(__xludf.DUMMYFUNCTION("C18*IMPORTRANGE(""https://docs.google.com/spreadsheets/d/1xsp01RMmkav9iTy39Zaj_7tE9677EGlOJ14KU9TZn7I"", ""2018-2025!AC319"")"),8044.582572899999) -> 8044.5826 | G18: Capital IQ
A19: 43543 | B19: 183 | C19: =38808.7/1000 -> 38.8087 | D19: =IFERROR(__xludf.DUMMYFUNCTION("C19*IMPORTRANGE(""https://docs.google.com/spreadsheets/d/1xsp01RMmkav9iTy39Zaj_7tE9677EGlOJ14KU9TZn7I"", ""2018-2025!H341"")"),34.301457582) -> 34.301458 | E19: =IFERROR(__xludf.DUMMYFUNCTION("C19*IMPORTRANGE(""https://docs.google.com/spreadsheets/d/1xsp01RMmkav9iTy39Zaj_7tE9677EGlOJ14KU9TZn7I"", ""2018-2025!T341"")"),29.385947639999994) -> 29.385948 | F19: =IFERROR(__xludf.DUMMYFUNCTION("C19*IMPORTRANGE(""https://docs.google.com/spreadsheets/d/1xsp01RMmkav9iTy39Zaj_7tE9677EGlOJ14KU9TZn7I"", ""2018-2025!AC341"")"),4321.038275399999) -> 4321.0383 | G19: Capital IQ
A20: 43574 | B20: 174 | C20: =28314.2/1000 -> 28.3142 | D20: =IFERROR(__xludf.DUMMYFUNCTION("C20*IMPORTRANGE(""https://docs.google.com/spreadsheets/d/1xsp01RMmkav9iTy39Zaj_7tE9677EGlOJ14KU9TZn7I"", ""2018-2025!H364"")"),25.190011172) -> 25.190011 | E20: =IFERROR(__xludf.DUMMYFUNCTION("C20*IMPORTRANGE(""https://docs.google.com/spreadsheets/d/1xsp01RMmkav9iTy39Zaj_7tE9677EGlOJ14KU9TZn7I"", ""2018-2025!T364"")"),21.708638711) -> 21.708639 | F20: =IFERROR(__xludf.DUMMYFUNCTION("C20*IMPORTRANGE(""https://docs.google.com/spreadsheets/d/1xsp01RMmkav9iTy39Zaj_7tE9677EGlOJ14KU9TZn7I"", ""2018-2025!AC364"")"),3161.7759285) -> 3161.7759 | G20: Capital IQ
A21: 43604 | B21: 169 | C21: =25545.7/1000 -> 25.5457 | D21: =IFERROR(__xludf.DUMMYFUNCTION("C21*IMPORTRANGE(""https://docs.google.com/spreadsheets/d/1xsp01RMmkav9iTy39Zaj_7tE9677EGlOJ14KU9TZn7I"", ""2018-2025!H388"")"),22.824061122) -> 22.824061 | E21: =IFERROR(__xludf.DUMMYFUNCTION("C21*IMPORTRANGE(""https://docs.google.com/spreadsheets/d/1xsp01RMmkav9iTy39Zaj_7tE9677EGlOJ14KU9TZn7I"", ""2018-2025!T388"")"),19.838279706) -> 19.83828 | F21: =IFERROR(__xludf.DUMMYFUNCTION("C21*IMPORTRANGE(""https://docs.google.com/spreadsheets/d/1xsp01RMmkav9iTy39Zaj_7tE9677EGlOJ14KU9TZn7I"", ""2018-2025!AC388"")"),2805.9141423) -> 2805.9141 | G21: Capital IQ
A22: 43635 | B22: 167 | C22: =46795.4/1000 -> 46.7954 | D22: =IFERROR(__xludf.DUMMYFUNCTION("C22*IMPORTRANGE(""https://docs.google.com/spreadsheets/d/1xsp01RMmkav9iTy39Zaj_7tE9677EGlOJ14KU9TZn7I"", ""2018-2025!H409"")"),41.455810883) -> 41.455811 | E22: =IFERROR(__xludf.DUMMYFUNCTION("C22*IMPORTRANGE(""https://docs.google.com/spreadsheets/d/1xsp01RMmkav9iTy39Zaj_7tE9677EGlOJ14KU9TZn7I"", ""2018-2025!T409"")"),36.873137361000005) -> 36.873137 | F22: =IFERROR(__xludf.DUMMYFUNCTION("C22*IMPORTRANGE(""https://docs.google.com/spreadsheets/d/1xsp01RMmkav9iTy39Zaj_7tE9677EGlOJ14KU9TZn7I"", ""2018-2025!AC409"")"),5067.356877499999) -> 5067.3569 | G22: Capital IQ
A23: 43665 | B23: 191 | C23: =52900.6/1000 -> 52.9006 | D23: =IFERROR(__xludf.DUMMYFUNCTION("C23*IMPORTRANGE(""https://docs.google.com/spreadsheets/d/1xsp01RMmkav9iTy39Zaj_7tE9677EGlOJ14KU9TZn7I"", ""2018-2025!H433"")"),47.117506408) -> 47.117506 | E23: =IFERROR(__xludf.DUMMYFUNCTION("C23*IMPORTRANGE(""https://docs.google.com/spreadsheets/d/1xsp01RMmkav9iTy39Zaj_7tE9677EGlOJ14KU9TZn7I"", ""2018-2025!T433"")"),42.277101508) -> 42.277102 | F23: =IFERROR(__xludf.DUMMYFUNCTION("C23*IMPORTRANGE(""https://docs.google.com/spreadsheets/d/1xsp01RMmkav9iTy39Zaj_7tE9677EGlOJ14KU9TZn7I"", ""2018-2025!AC433"")"),5725.5377392) -> 5725.5377 | G23: Capital IQ
A24: 43696 | B24: 181 | C24: =26209.3/1000 -> 26.2093 | D24: =IFERROR(__xludf.DUMMYFUNCTION("C24*IMPORTRANGE(""https://docs.google.com/spreadsheets/d/1xsp01RMmkav9iTy39Zaj_7tE9677EGlOJ14KU9TZn7I"", ""2018-2025!H456"")"),23.5995089525) -> 23.599509 | E24: =IFERROR(__xludf.DUMMYFUNCTION("C24*IMPORTRANGE(""https://docs.google.com/spreadsheets/d/1xsp01RMmkav9iTy39Zaj_7tE9677EGlOJ14KU9TZn7I"", ""2018-2025!T456"")"),21.5661914585) -> 21.566191 | F24: =IFERROR(__xludf.DUMMYFUNCTION("C24*IMPORTRANGE(""https://docs.google.com/spreadsheets/d/1xsp01RMmkav9iTy39Zaj_7tE9677EGlOJ14KU9TZn7I"", ""2018-2025!AC456"")"),2783.36213675) -> 2783.3621 | G24: Capital IQ
A25: 43727 | B25: 196 | C25: =26203.8/1000 -> 26.2038 | D25: =IFERROR(__xludf.DUMMYFUNCTION("C25*IMPORTRANGE(""https://docs.google.com/spreadsheets/d/1xsp01RMmkav9iTy39Zaj_7tE9677EGlOJ14KU9TZn7I"", ""2018-2025!H478"")"),23.780472575999998) -> 23.780473 | E25: =IFERROR(__xludf.DUMMYFUNCTION("C25*IMPORTRANGE(""https://docs.google.com/spreadsheets/d/1xsp01RMmkav9iTy39Zaj_7tE9677EGlOJ14KU9TZn7I"", ""2018-2025!T478"")"),21.225602075999998) -> 21.225602 | F25: =IFERROR(__xludf.DUMMYFUNCTION("C25*IMPORTRANGE(""https://docs.google.com/spreadsheets/d/1xsp01RMmkav9iTy39Zaj_7tE9677EGlOJ14KU9TZn7I"", ""2018-2025!AC478"")"),2820.8914775999997) -> 2820.8915 | G25: Capital IQ
A26: 44123 | B26: 192 | C26: =109690.6/1000 -> 109.6906 | D26: =IFERROR(__xludf.DUMMYFUNCTION("C26*IMPORTRANGE(""https://docs.google.com/spreadsheets/d/1xsp01RMmkav9iTy39Zaj_7tE9677EGlOJ14KU9TZn7I"", ""2018-2025!H502"")"),99.404912438) -> 99.404912 | E26: =IFERROR(__xludf.DUMMYFUNCTION("C26*IMPORTRANGE(""https://docs.google.com/spreadsheets/d/1xsp01RMmkav9iTy39Zaj_7tE9677EGlOJ14KU9TZn7I"", ""2018-2025!T502"")"),85.960135596) -> 85.960136 | F26: =IFERROR(__xludf.DUMMYFUNCTION("C26*IMPORTRANGE(""https://docs.google.com/spreadsheets/d/1xsp01RMmkav9iTy39Zaj_7tE9677EGlOJ14KU9TZn7I"", ""2018-2025!AC502"")"),11896.9327854) -> 11896.933 | G26: Capital IQ
A27: 43788 | B27: 190 | C27: =48655.4/1000 -> 48.6554 | D27: =IFERROR(__xludf.DUMMYFUNCTION("C27*IMPORTRANGE(""https://docs.google.com/spreadsheets/d/1xsp01RMmkav9iTy39Zaj_7tE9677EGlOJ14KU9TZn7I"", ""2018-2025!H524"")"),44.090063818000004) -> 44.090064 | E27: =IFERROR(__xludf.DUMMYFUNCTION("C27*IMPORTRANGE(""https://docs.google.com/spreadsheets/d/1xsp01RMmkav9iTy39Zaj_7tE9677EGlOJ14KU9TZn7I"", ""2018-2025!T524"")"),37.741993779999994) -> 37.741994 | F27: =IFERROR(__xludf.DUMMYFUNCTION("C27*IMPORTRANGE(""https://docs.google.com/spreadsheets/d/1xsp01RMmkav9iTy39Zaj_7tE9677EGlOJ14KU9TZn7I"", ""2018-2025!AC524"")"),5293.6102092) -> 5293.6102 | G27: Capital IQ
A28: 43818 | B28: 220 | C28: =37045.6/1000 -> 37.0456 | D28: =IFERROR(__xludf.DUMMYFUNCTION("C28*IMPORTRANGE(""https://docs.google.com/spreadsheets/d/1xsp01RMmkav9iTy39Zaj_7tE9677EGlOJ14KU9TZn7I"", ""2018-2025!H547"")"),33.379567424) -> 33.379567 | E28: =IFERROR(__xludf.DUMMYFUNCTION("C28*IMPORTRANGE(""https://docs.google.com/spreadsheets/d/1xsp01RMmkav9iTy39Zaj_7tE9677EGlOJ14KU9TZn7I"", ""2018-2025!T547"")"),28.275609883999998) -> 28.27561 | F28: =IFERROR(__xludf.DUMMYFUNCTION("C28*IMPORTRANGE(""https://docs.google.com/spreadsheets/d/1xsp01RMmkav9iTy39Zaj_7tE9677EGlOJ14KU9TZn7I"", ""2018-2025!AC547"")"),4052.1403419999997) -> 4052.1403 | G28: Capital IQ
A29: 2020
A30: 43850 | B30: 181 | C30: =35075.5/1000 -> 35.0755 | D30: =IFERROR(__xludf.DUMMYFUNCTION("C30*IMPORTRANGE(""https://docs.google.com/spreadsheets/d/1xsp01RMmkav9iTy39Zaj_7tE9677EGlOJ14KU9TZn7I"", ""2018-2025!H572"")"),31.561987164999998) -> 31.561987 | E30: =IFERROR(__xludf.DUMMYFUNCTION("C30*IMPORTRANGE(""https://docs.google.com/spreadsheets/d/1xsp01RMmkav9iTy39Zaj_7tE9677EGlOJ14KU9TZn7I"", ""2018-2025!T572"")"),26.836265049999998) -> 26.836265 | F30: =IFERROR(__xludf.DUMMYFUNCTION("C30*IMPORTRANGE(""https://docs.google.com/spreadsheets/d/1xsp01RMmkav9iTy39Zaj_7tE9677EGlOJ14KU9TZn7I"", ""2018-2025!AC572"")"),3827.859466) -> 3827.8595 | G30: Capital IQ
A31: 43881 | B31: 190 | C31: =67924.3/1000 -> 67.9243 | D31: =IFERROR(__xludf.DUMMYFUNCTION("C31*IMPORTRANGE(""https://docs.google.com/spreadsheets/d/1xsp01RMmkav9iTy39Zaj_7tE9677EGlOJ14KU9TZn7I"", ""2018-2025!H593"")"),62.4078279755) -> 62.407828 | E31: =IFERROR(__xludf.DUMMYFUNCTION("C31*IMPORTRANGE(""https://docs.google.com/spreadsheets/d/1xsp01RMmkav9iTy39Zaj_7tE9677EGlOJ14KU9TZn7I"", ""2018-2025!T593"")"),52.422616254000005) -> 52.422616 | F31: =IFERROR(__xludf.DUMMYFUNCTION("C31*IMPORTRANGE(""https://docs.google.com/spreadsheets/d/1xsp01RMmkav9iTy39Zaj_7tE9677EGlOJ14KU9TZn7I"", ""2018-2025!AC593"")"),7460.56737695) -> 7460.5674 | G31: Capital IQ
A32: 43910 | B32: 137 | C32: =64558.5/1000 -> 64.5585 | D32: =IFERROR(__xludf.DUMMYFUNCTION("C32*IMPORTRANGE(""https://docs.google.com/spreadsheets/d/1xsp01RMmkav9iTy39Zaj_7tE9677EGlOJ14KU9TZn7I"", ""2018-2025!H616"")"),57.956747789999994) -> 57.956748 | E32: =IFERROR(__xludf.DUMMYFUNCTION("C32*IMPORTRANGE(""https://docs.google.com/spreadsheets/d/1xsp01RMmkav9iTy39Zaj_7tE9677EGlOJ14KU9TZn7I"", ""2018-2025!T616"")"),51.952419938999995) -> 51.95242 | F32: =IFERROR(__xludf.DUMMYFUNCTION("C32*IMPORTRANGE(""https://docs.google.com/spreadsheets/d/1xsp01RMmkav9iTy39Zaj_7tE9677EGlOJ14KU9TZn7I"", ""2018-2025!AC616"")"),6942.9438825) -> 6942.9439 | G32: Capital IQ
A33: 43941 | B33: 107 | C33: =16741/1000 -> 16.741 | D33: =IFERROR(__xludf.DUMMYFUNCTION("C33*IMPORTRANGE(""https://docs.google.com/spreadsheets/d/1xsp01RMmkav9iTy39Zaj_7tE9677EGlOJ14KU9TZn7I"", ""2018-2025!H639"")"),15.40925345) -> 15.409253 | E33: =IFERROR(__xludf.DUMMYFUNCTION("C33*IMPORTRANGE(""https://docs.google.com/spreadsheets/d/1xsp01RMmkav9iTy39Zaj_7tE9677EGlOJ14KU9TZn7I"", ""2018-2025!T639"")"),13.48387104) -> 13.483871 | F33: =IFERROR(__xludf.DUMMYFUNCTION("C33*IMPORTRANGE(""https://docs.google.com/spreadsheets/d/1xsp01RMmkav9iTy39Zaj_7tE9677EGlOJ14KU9TZn7I"", ""2018-2025!AC639"")"),1802.4950995) -> 1802.4951 | G33: Capital IQ
A34: 43971 | B34: 125 | C34: =5455.7/1000 -> 5.4557 | D34: =IFERROR(__xludf.DUMMYFUNCTION("C34*IMPORTRANGE(""https://docs.google.com/spreadsheets/d/1xsp01RMmkav9iTy39Zaj_7tE9677EGlOJ14KU9TZn7I"", ""2018-2025!H661"")"),5.003258799) -> 5.0032588 | E34: =IFERROR(__xludf.DUMMYFUNCTION("C34*IMPORTRANGE(""https://docs.google.com/spreadsheets/d/1xsp01RMmkav9iTy39Zaj_7tE9677EGlOJ14KU9TZn7I"", ""2018-2025!T661"")"),4.448250438) -> 4.4482504 | F34: =IFERROR(__xludf.DUMMYFUNCTION("C34*IMPORTRANGE(""https://docs.google.com/spreadsheets/d/1xsp01RMmkav9iTy39Zaj_7tE9677EGlOJ14KU9TZn7I"", ""2018-2025!AC661"")"),585.7512305) -> 585.75123 | G34: Capital IQ
A35: 44002 | B35: 119 | C35: =13207.8/1000 -> 13.2078 | D35: =IFERROR(__xludf.DUMMYFUNCTION("C35*IMPORTRANGE(""https://docs.google.com/spreadsheets/d/1xsp01RMmkav9iTy39Zaj_7tE9677EGlOJ14KU9TZn7I"", ""2018-2025!H684"")"),11.738762444999999) -> 11.738762 | E35: =IFERROR(__xludf.DUMMYFUNCTION("C35*IMPORTRANGE(""https://docs.google.com/spreadsheets/d/1xsp01RMmkav9iTy39Zaj_7tE9677EGlOJ14KU9TZn7I"", ""2018-2025!T684"")"),10.533550694999999) -> 10.533551 | F35: =IFERROR(__xludf.DUMMYFUNCTION("C35*IMPORTRANGE(""https://docs.google.com/spreadsheets/d/1xsp01RMmkav9iTy39Zaj_7tE9677EGlOJ14KU9TZn7I"", ""2018-2025!AC684"")"),1417.9960119) -> 1417.996 | G35: Capital IQ
A36: 44397 | B36: 142 | C36: =28843.8/1000 -> 28.8438 | D36: =IFERROR(__xludf.DUMMYFUNCTION("C36*IMPORTRANGE(""https://docs.google.com/spreadsheets/d/1xsp01RMmkav9iTy39Zaj_7tE9677EGlOJ14KU9TZn7I"", ""2018-2025!H708"")"),25.277841006) -> 25.277841 | E36: =IFERROR(__xludf.DUMMYFUNCTION("C36*IMPORTRANGE(""https://docs.google.com/spreadsheets/d/1xsp01RMmkav9iTy39Zaj_7tE9677EGlOJ14KU9TZn7I"", ""2018-2025!T708"")"),22.882651854) -> 22.882652 | F36: =IFERROR(__xludf.DUMMYFUNCTION("C36*IMPORTRANGE(""https://docs.google.com/spreadsheets/d/1xsp01RMmkav9iTy39Zaj_7tE9677EGlOJ14KU9TZn7I"", ""2018-2025!AC708"")"),3091.9399848) -> 3091.94 | G36: Capital IQ
A37: 44428 | B37: 187 | C37: =33842.1/1000 -> 33.8421 | D37: =IFERROR(__xludf.DUMMYFUNCTION("C37*IMPORTRANGE(""https://docs.google.com/spreadsheets/d/1xsp01RMmkav9iTy39Zaj_7tE9677EGlOJ14KU9TZn7I"", ""2018-2025!H730"")"),28.632108705) -> 28.632109 | E37: =IFERROR(__xludf.DUMMYFUNCTION("C37*IMPORTRANGE(""https://docs.google.com/spreadsheets/d/1xsp01RMmkav9iTy39Zaj_7tE9677EGlOJ14KU9TZn7I"", ""2018-2025!T730"")"),25.819864037100004) -> 25.819864 | F37: =IFERROR(__xludf.DUMMYFUNCTION("C37*IMPORTRANGE(""https://docs.google.com/spreadsheets/d/1xsp01RMmkav9iTy39Zaj_7tE9677EGlOJ14KU9TZn7I"", ""2018-2025!AC730"")"),3586.9918632000004) -> 3586.9919 | G37: Capital IQ
A38: Sep-20 | B38: 173 | C38: =29980/1000 -> 29.98 | D38: =IFERROR(__xludf.DUMMYFUNCTION("C38*IMPORTRANGE(""https://docs.google.com/spreadsheets/d/1xsp01RMmkav9iTy39Zaj_7tE9677EGlOJ14KU9TZn7I"", ""2018-2025!H753"")"),25.3572339) -> 25.357234 | E38: =IFERROR(__xludf.DUMMYFUNCTION("C38*IMPORTRANGE(""https://docs.google.com/spreadsheets/d/1xsp01RMmkav9iTy39Zaj_7tE9677EGlOJ14KU9TZn7I"", ""2018-2025!T753"")"),23.224606599999998) -> 23.224607 | F38: =IFERROR(__xludf.DUMMYFUNCTION("C38*IMPORTRANGE(""https://docs.google.com/spreadsheets/d/1xsp01RMmkav9iTy39Zaj_7tE9677EGlOJ14KU9TZn7I"", ""2018-2025!AC753"")"),3168.57121) -> 3168.5712 | G38: Capital IQ
A39: 44489 | B39: 230 | C39: =68099.7/1000 -> 68.0997 | D39: =IFERROR(__xludf.DUMMYFUNCTION("C39*IMPORTRANGE(""https://docs.google.com/spreadsheets/d/1xsp01RMmkav9iTy39Zaj_7tE9677EGlOJ14KU9TZn7I"", ""2018-2025!H776"")"),57.8722827549) -> 57.872283 | E39: =IFERROR(__xludf.DUMMYFUNCTION("C39*IMPORTRANGE(""https://docs.google.com/spreadsheets/d/1xsp01RMmkav9iTy39Zaj_7tE9677EGlOJ14KU9TZn7I"", ""2018-2025!T776"")"),52.581140364) -> 52.58114 | F39: =IFERROR(__xludf.DUMMYFUNCTION("C39*IMPORTRANGE(""https://docs.google.com/spreadsheets/d/1xsp01RMmkav9iTy39Zaj_7tE9677EGlOJ14KU9TZn7I"", ""2018-2025!AC776"")"),7180.3642683) -> 7180.3643 | G39: Capital IQ
A40: 44520 | B40: 227 | C40: =113284.1/1000 -> 113.2841 | D40: =IFERROR(__xludf.DUMMYFUNCTION("C40*IMPORTRANGE(""https://docs.google.com/spreadsheets/d/1xsp01RMmkav9iTy39Zaj_7tE9677EGlOJ14KU9TZn7I"", ""2018-2025!H798"")"),95.63670290200001) -> 95.636703 | E40: =IFERROR(__xludf.DUMMYFUNCTION("C40*IMPORTRANGE(""https://docs.google.com/spreadsheets/d/1xsp01RMmkav9iTy39Zaj_7tE9677EGlOJ14KU9TZn7I"", ""2018-2025!T798"")"),85.664303579) -> 85.664304 | F40: =IFERROR(__xludf.DUMMYFUNCTION("C40*IMPORTRANGE(""https://docs.google.com/spreadsheets/d/1xsp01RMmkav9iTy39Zaj_7tE9677EGlOJ14KU9TZn7I"", ""2018-2025!AC798"")"),11839.661143300002) -> 11839.661 | G40: Capital IQ
...
