Workbook

Sheet Annually
A1: Year | B1: Number of Deals | C1: Value | G1: Source
C2: in bil. USD | D2: in bil. EUR | E2: in bil. GBP | F2: in bil. YEN
A3: 1985 | B3: 2676 | C3: 347 | D3: 456.47 | E3: 269.66 | F3: 80103.44 | G3: Thomson Financial
A4: 1986 | B4: 4228 | C4: 435 | D4: 441.71 | E4: 297.09 | F4: 71031.2 | G4: Thomson Financial
A5: 1987 | B5: 5279 | C5: 506 | D5: 441.07 | E5: 310.79 | F5: 71584.62 | G5: Thomson Financial
A6: 1988 | B6: 7440 | C6: 777 | D6: 661.87 | E6: 440.43 | F6: 99339.48 | G6: Thomson Financial
A7: 1989 | B7: 10135 | C7: 758 | D7: 685.42 | E7: 461.88 | F7: 105967.85 | G7: Thomson Financial
A8: 1990 | B8: 10814 | C8: 540 | D8: 423.4 | E8: 304.46 | F8: 77208.59 | G8: Thomson Financial
A9: 1991 | B9: 14722 | C9: 397 | D9: 317.22 | E9: 225.61 | F9: 53167.05 | G9: Thomson Financial
A10: 1992 | B10: 14102 | C10: 400 | D10: 308.94 | E10: 231.22 | F10: 50171.3 | G10: Thomson Financial
A11: 1993 | B11: 14772 | C11: 516 | D11: 436.86 | E11: 338.72 | F11: 56189.72 | G11: Thomson Financial
A12: 1994 | B12: 16816 | C12: 624 | D12: 521.34 | E12: 405.27 | F12: 63075.94 | G12: Thomson Financial
A13: 1995 | B13: 20278 | C13: 1039 | D13: 810.47 | E13: 658.98 | F13: 98400.07 | G13: Thomson Financial
A14: 1996 | B14: 24310 | C14: 1217 | D14: 971.2 | E14: 777.04 | F14: 133278.96 | G14: Thomson Financial
... A35: 2017 | B35: 53302 | C35: 3777 | D35: 3339.5644 | E35: 2923.6767 | F35: 423152.82 | G35: Thomson Financial
A36: 2018 | B36: =SUM(Quaterly!B136:B139) -> 56382 | C36: =SUM(Quaterly!C136:C139) -> 3939.2729 | D36: =SUM(Quaterly!D136:D139) -> 3322.573 | E36: =SUM(Quaterly!E136:E139) -> 2845.2451 | F36: =SUM(Quaterly!F136:F139) -> 402886.74 | G36: Capital IQ | I36: Total Since 1985 | J36: Number of Deals | K36: Value of Deals
A37: 2019 | B37: =SUM(Quaterly!B141:B144) -> 53594 | C37: =SUM(Quaterly!C141:C144) -> 3893.9129 | D37: =SUM(Quaterly!D141:D144) -> 3476.8916 | E37: =SUM(Quaterly!E141:E144) -> 3040.7212 | F37: =SUM(Quaterly!F141:F144) -> 425121.4 | G37: Capital IQ | J37: =SUM(B3:B44) -> 1363221 | K37: =SUM(C3:C44) -> 100171.27
A38: 2020 | B38: =SUM(Quaterly!B146:B149) -> 47307 | C38: =SUM(Quaterly!C146:C149) -> 3268.4942 | D38: =SUM(Quaterly!D146:D149) -> 2822.1191 | E38: =SUM(Quaterly!E146:E149) -> 2524.0138 | F38: =SUM(Quaterly!F146:F149) -> 347129.24 | G38: Capital IQ
A39: 2021 | B39: =SUM(Quaterly!B151:B154) -> 58308 | C39: =SUM(Quaterly!C151:C154) -> 5235.6476 | D39: =SUM(Quaterly!D151:D154) -> 4422.5275 | E39: =SUM(Quaterly!E151:E154) -> 3802.0454 | F39: =SUM(Quaterly!F151:F154) -> 575006.97 | G39: Capital IQ
A40: 2022 | B40: =SUM(Quaterly!B156:B159) -> 50763 | C40: =SUM(Quaterly!C156:C159) -> 3383.7938 | D40: =SUM(Quaterly!D156:D159) -> 3188.2959 | E40: =SUM(Quaterly!E156:E159) -> 2708.5413 | F40: =SUM(Quaterly!F156:F159) -> 438472.31 | G40: Capital IQ
A41: 2023 | B41: =SUM(Monthly!B465:B476) -> 39603 | C41: =SUM(Monthly!C465:C476) -> 2495.0571 | D41: =SUM(Monthly!D465:D476) -> 2308.7549 | E41: =SUM(Monthly!E465:E476) -> 2009.9499 | F41: =SUM(Monthly!F465:F476) -> 345565.38 | G41: Capital IQ
A42: 2024 | B42: =SUM(Monthly!B478:B489) -> 36067 | C42: =SUM(Monthly!C478:C489) -> 2626.888 | D42: =SUM(Monthly!D478:D489) -> 2432.7492 | E42: =SUM(Monthly!E478:E489) -> 2054.1794 | F42: =SUM(Monthly!F478:F489) -> 397404.47 | G42: Capital IQ
A43: 2025 | B43: =SUM(Monthly!B491:B502) -> 39494 | C43: =SUM(Monthly!C491:C502) -> 4036.8502 | D43: =SUM(Monthly!D491:D502) -> 3557.9097 | E43: =SUM(Monthly!E491:E502) -> 3052.79 | F43: =SUM(Monthly!F491:F502) -> 605393.29 | G43: Capital IQ
A44: 2026 (Mar 31) | B44: =SUM(Monthly!B504:B506) -> 10167 | C44: =SUM(Monthly!C504:C506) -> 1182.3581 | D44: =SUM(Monthly!D504:D506) -> 1014.8963 | E44: =SUM(Monthly!E504:E506) -> 921.51544 | F44: =SUM(Monthly!F504:F506) -> 185410.29 | G44: Capital IQ
A45: 2026 e | B45: =B44/3*12 -> 40668 | C45: =C44/3*12 -> 4729.4324 | D45: =D44/3*12 -> 4059.5853 | E45: =E44/3*12 -> 3686.0618 | F45: =F44/3*12 -> 741641.16 | G45: Capital IQ

Sheet Monthly
A1: Month | B1: Number | C1: Value
C2: in bil. USD | D2: in bil. EUR | E2: in bil. GBP | F2: in bil. YEN
A3: Jan-85 | B3: 225 | C3: 18.26768 | D3: 25.59808 | E3: 15.73745 | F3: 4605.2105 | G3: Thomson Financial
A4: Feb-85 | B4: 188 | C4: 19.17313 | D4: 27.35183 | E4: 16.63414 | F4: 4958.3994 | G4: Thomson Financial
A5: Mar-85 | B5: 212 | C5: 30.17555 | D5: 43.93405 | E5: 26.6221 | F5: 7737.3946 | G5: Thomson Financial
A6: Apr-85 | B6: 244 | C6: 46.18231 | D6: 65.04246 | E6: 38.76813 | F6: 11487.031 | G6: Thomson Financial
A7: May-85 | B7: 196 | C7: 33.12994 | D7: 45.28524 | E7: 26.36187 | F7: 8030.2716 | G7: Thomson Financial
A8: Jun-85 | B8: 191 | C8: 28.95511 | D8: 39.68053 | E8: 22.87232 | F8: 7018.3473 | G8: Thomson Financial
A9: Jul-85 | B9: 204 | C9: 21.73952 | D9: 28.92675 | E9: 16.48867 | F9: 5190.2813 | G9: Thomson Financial
A10: Aug-85 | B10: 207 | C10: 21.84764 | D10: 27.48604 | E10: 15.79906 | F10: 4929.0663 | G10: Thomson Financial
A11: Sep-85 | B11: 188 | C11: 23.13002 | D11: 29.08697 | E11: 16.80667 | F11: 5241.1363 | G11: Thomson Financial
A12: Oct-85 | B12: 240 | C12: 35.07567 | D12: 42.94418 | E12: 25.14846 | F12: 7288.8125 | G12: Thomson Financial
A13: Nov-85 | B13: 189 | C13: 21.58458 | D13: 25.91556 | E13: 15.20765 | F13: 4204.1136 | G13: Thomson Financial
A14: Dec-85 | B14: 392 | C14: 48.01459 | D14: 55.21873 | E14: 33.21738 | F14: 9406.6434 | G14: Thomson Financial
... A194: Dec-00 | B194: 3190 | C194: 207.61874 | D194: 231.10234 | E194: 141.78802 | F194: 23413.704 | G194: Thomson Financial
A195: 43466 | B195: 2922 | C195: 117.79819 | D195: 127.18872 | E195: 80.19322 | F195: 13827.749 | G195: Thomson Financial
A196: 43497 | B196: 2681 | C196: 203.32612 | D196: 222.28828 | E196: 140.07105 | F196: 23824.814 | G196: Thomson Financial
A197: 43525 | B197: 2930 | C197: 171.52147 | D197: 188.92156 | E197: 118.6299 | F197: 20798.642 | G197: Thomson Financial
A198: 43556 | B198: 2762 | C198: 169.81407 | D198: 189.509 | E198: 118.06911 | F198: 21148.448 | G198: Thomson Financial
A199: 43586 | B199: 2978 | C199: 205.99281 | D199: 232.13902 | E199: 143.08319 | F199: 25091.212 | G199: Thomson Financial
A200: 43617 | B200: 2681 | C200: 117.46956 | D200: 136.89498 | E200: 83.15594 | F200: 14425.901 | G200: Thomson Financial
A201: 43647 | B201: 2766 | C201: 211.24419 | D201: 244.99223 | E201: 148.82021 | F201: 26327.989 | G201: Thomson Financial
A202: 43678 | B202: 2277 | C202: 127.6339 | D202: 143.92257 | E202: 89.186 | F202: 15684.515 | G202: Thomson Financial
A203: 43709 | B203: 1930 | C203: 147.18845 | D203: 161.77254 | E203: 100.82507 | F203: 17593.274 | G203: Thomson Financial
A204: 43739 | B204: 2536 | C204: 113.84221 | D204: 126.03956 | E204: 78.45636 | F204: 13955.43 | G204: Thomson Financial
A205: 43770 | B205: 2423 | C205: 142.92701 | D205: 160.46126 | E205: 99.34601 | F205: 17651.37 | G205: Thomson Financial
A206: 43800 | B206: 2326 | C206: 141.21216 | D206: 157.58477 | E206: 97.80789 | F206: 17940.358 | G206: Thomson Financial
... A398: 43816 | B398: 5012 | C398: 495.27714 | D398: 421.53917 | E398: 371.97412 | F398: 55482.675 | G398: Thomson Financial
A399: 2018
A400: 43118 | B400: 5112 | C400: 315.4 | D400: =IFERROR(__xludf.DUMMYFUNCTION("C400*IMPORTRANGE(""https://docs.google.com/spreadsheets/d/1xsp01RMmkav9iTy39Zaj_7tE9677EGlOJ14KU9TZn7I"", ""2018-2025!H25"")"),258.68792599999995) -> 258.68793 | E400: =IFERROR(__xludf.DUMMYFUNCTION("C400*IMPORTRANGE(""https://docs.google.com/spreadsheets/d/1xsp01RMmkav9iTy39Zaj_7tE9677EGlOJ14KU9TZn7I"", ""2018-2025!T25"")"),228.57984199999999) -> 228.57984 | F400: =IFERROR(__xludf.DUMMYFUNCTION("C400*IMPORTRANGE(""https://docs.google.com/spreadsheets/d/1xsp01RMmkav9iTy39Zaj_7tE9677EGlOJ14KU9TZn7I"", ""2018-2025!AC25"")"),35040.939999999995) -> 35040.94 | G400: Capital IQ
A401: 44975 | B401: 4518 | C401: 295.2 | D401: =IFERROR(__xludf.DUMMYFUNCTION("C401*IMPORTRANGE(""https://docs.google.com/spreadsheets/d/1xsp01RMmkav9iTy39Zaj_7tE9677EGlOJ14KU9TZn7I"", ""2018-2025!H46"")"),239.13413999999997) -> 239.13414 | E401: =IFERROR(__xludf.DUMMYFUNCTION("C401*IMPORTRANGE(""https://docs.google.com/spreadsheets/d/1xsp01RMmkav9iTy39Zaj_7tE9677EGlOJ14KU9TZn7I"", ""2018-2025!T46"")"),211.42224) -> 211.42224 | F401: =IFERROR(__xludf.DUMMYFUNCTION("C401*IMPORTRANGE(""https://docs.google.com/spreadsheets/d/1xsp01RMmkav9iTy39Zaj_7tE9677EGlOJ14KU9TZn7I"", ""2018-2025!AC46"")"),31781.084399999996) -> 31781.084 | G401: Capital IQ
A402: 45003 | B402: 4862 | C402: 430 | D402: =IFERROR(__xludf.DUMMYFUNCTION("C402*IMPORTRANGE(""https://docs.google.com/spreadsheets/d/1xsp01RMmkav9iTy39Zaj_7tE9677EGlOJ14KU9TZn7I"", ""2018-2025!H69"")"),348.7214) -> 348.7214 | E402: =IFERROR(__xludf.DUMMYFUNCTION("D402*IMPORTRANGE(""https://docs.google.com/spreadsheets/d/1xsp01RMmkav9iTy39Zaj_7tE9677EGlOJ14KU9TZn7I"", ""2018-2025!t69"")"),249.844934244) -> 249.84493 | F402: =IFERROR(__xludf.DUMMYFUNCTION("E402*IMPORTRANGE(""https://docs.google.com/spreadsheets/d/1xsp01RMmkav9iTy39Zaj_7tE9677EGlOJ14KU9TZn7I"", ""2018-2025!ac69"")"),26527.160970889578) -> 26527.161 | G402: Capital IQ
A403: 45034 | B403: 4579 | C403: 479 | D403: =IFERROR(__xludf.DUMMYFUNCTION("C403*IMPORTRANGE(""https://docs.google.com/spreadsheets/d/1xsp01RMmkav9iTy39Zaj_7tE9677EGlOJ14KU9TZn7I"", ""2018-2025!H91"")"),389.66171) -> 389.66171 | E403: =IFERROR(__xludf.DUMMYFUNCTION("C403*IMPORTRANGE(""https://docs.google.com/spreadsheets/d/1xsp01RMmkav9iTy39Zaj_7tE9677EGlOJ14KU9TZn7I"", ""2018-2025!t91"")"),340.0421) -> 340.0421 | F403: =IFERROR(__xludf.DUMMYFUNCTION("C403*IMPORTRANGE(""https://docs.google.com/spreadsheets/d/1xsp01RMmkav9iTy39Zaj_7tE9677EGlOJ14KU9TZn7I"", ""2018-2025!ac91"")"),51307.127) -> 51307.127 | G403: Capital IQ
A404: 45064 | B404: 4572 | C404: 420.82 | D404: =IFERROR(__xludf.DUMMYFUNCTION("C404*IMPORTRANGE(""https://docs.google.com/spreadsheets/d/1xsp01RMmkav9iTy39Zaj_7tE9677EGlOJ14KU9TZn7I"", ""2018-2025!H115"")"),355.9968872) -> 355.99689 | E404: =IFERROR(__xludf.DUMMYFUNCTION("C404*IMPORTRANGE(""https://docs.google.com/spreadsheets/d/1xsp01RMmkav9iTy39Zaj_7tE9677EGlOJ14KU9TZn7I"", ""2018-2025!t115"")"),311.1795572) -> 311.17956 | F404: =IFERROR(__xludf.DUMMYFUNCTION("C404*IMPORTRANGE(""https://docs.google.com/spreadsheets/d/1xsp01RMmkav9iTy39Zaj_7tE9677EGlOJ14KU9TZn7I"", ""2018-2025!ac115"")"),46131.55086) -> 46131.551 | G404: Capital IQ
A405: 45095 | B405: 4483 | C405: 358.6 | D405: =IFERROR(__xludf.DUMMYFUNCTION("C405*IMPORTRANGE(""https://docs.google.com/spreadsheets/d/1xsp01RMmkav9iTy39Zaj_7tE9677EGlOJ14KU9TZn7I"", ""2018-2025!H137"")"),307.3202) -> 307.3202 | E405: =IFERROR(__xludf.DUMMYFUNCTION("C405*IMPORTRANGE(""https://docs.google.com/spreadsheets/d/1xsp01RMmkav9iTy39Zaj_7tE9677EGlOJ14KU9TZn7I"", ""2018-2025!T137"")"),270.06166) -> 270.06166 | F405: =IFERROR(__xludf.DUMMYFUNCTION("C405*IMPORTRANGE(""https://docs.google.com/spreadsheets/d/1xsp01RMmkav9iTy39Zaj_7tE9677EGlOJ14KU9TZn7I"", ""2018-2025!AC137"")"),39480.7842) -> 39480.784 | G405: Capital IQ
A406: 45125 | B406: 4717 | C406: 288 | D406: =IFERROR(__xludf.DUMMYFUNCTION("C406*IMPORTRANGE(""https://docs.google.com/spreadsheets/d/1xsp01RMmkav9iTy39Zaj_7tE9677EGlOJ14KU9TZn7I"", ""2018-2025!H160"")"),246.6) -> 246.6 | E406: =IFERROR(__xludf.DUMMYFUNCTION("D406*IMPORTRANGE(""https://docs.google.com/spreadsheets/d/1xsp01RMmkav9iTy39Zaj_7tE9677EGlOJ14KU9TZn7I"", ""2018-2025!T160"")"),186.99678) -> 186.99678 | F406: =IFERROR(__xludf.DUMMYFUNCTION("E406*IMPORTRANGE(""https://docs.google.com/spreadsheets/d/1xsp01RMmkav9iTy39Zaj_7tE9677EGlOJ14KU9TZn7I"", ""2018-2025!AC160"")"),20761.03700433) -> 20761.037 | G406: Capital IQ
A407: 45156 | B407: 4441 | C407: 277.8 | D407: =IFERROR(__xludf.DUMMYFUNCTION("C407*IMPORTRANGE(""https://docs.google.com/spreadsheets/d/1xsp01RMmkav9iTy39Zaj_7tE9677EGlOJ14KU9TZn7I"", ""2018-2025!H184"")"),239.96364000000003) -> 239.96364 | E407: =IFERROR(__xludf.DUMMYFUNCTION("C407*IMPORTRANGE(""https://docs.google.com/spreadsheets/d/1xsp01RMmkav9iTy39Zaj_7tE9677EGlOJ14KU9TZn7I"", ""2018-2025!T184"")"),215.65614) -> 215.65614 | F407: =IFERROR(__xludf.DUMMYFUNCTION("C407*IMPORTRANGE(""https://docs.google.com/spreadsheets/d/1xsp01RMmkav9iTy39Zaj_7tE9677EGlOJ14KU9TZn7I"", ""2018-2025!AC184"")"),30873.858600000003) -> 30873.859 | G407: Capital IQ
A408: 45187 | B408: 4393 | C408: 240.7 | D408: =IFERROR(__xludf.DUMMYFUNCTION("C408*IMPORTRANGE(""https://docs.google.com/spreadsheets/d/1xsp01RMmkav9iTy39Zaj_7tE9677EGlOJ14KU9TZn7I"", ""2018-2025!H205"")"),206.852766) -> 206.85277 | E408: =IFERROR(__xludf.DUMMYFUNCTION("C408*IMPORTRANGE(""https://docs.google.com/spreadsheets/d/1xsp01RMmkav9iTy39Zaj_7tE9677EGlOJ14KU9TZn7I"", ""2018-2025!T205"")"),184.077732) -> 184.07773 | F408: =IFERROR(__xludf.DUMMYFUNCTION("C408*IMPORTRANGE(""https://docs.google.com/spreadsheets/d/1xsp01RMmkav9iTy39Zaj_7tE9677EGlOJ14KU9TZn7I"", ""2018-2025!AC205"")"),26915.43505) -> 26915.435 | G408: Capital IQ
A409: 45217 | B409: 4998 | C409: 343.8 | D409: =IFERROR(__xludf.DUMMYFUNCTION("C409*IMPORTRANGE(""https://docs.google.com/spreadsheets/d/1xsp01RMmkav9iTy39Zaj_7tE9677EGlOJ14KU9TZn7I"", ""2018-2025!H229"")"),298.775952) -> 298.77595 | E409: =IFERROR(__xludf.DUMMYFUNCTION("C409*IMPORTRANGE(""https://docs.google.com/spreadsheets/d/1xsp01RMmkav9iTy39Zaj_7tE9677EGlOJ14KU9TZn7I"", ""2018-2025!T229"")"),263.53989) -> 263.53989 | F409: =IFERROR(__xludf.DUMMYFUNCTION("C409*IMPORTRANGE(""https://docs.google.com/spreadsheets/d/1xsp01RMmkav9iTy39Zaj_7tE9677EGlOJ14KU9TZn7I"", ""2018-2025!AC229"")"),38670.624) -> 38670.624 | G409: Capital IQ
A410: 45248 | B410: 4785 | C410: 264.8 | D410: =IFERROR(__xludf.DUMMYFUNCTION("C410*IMPORTRANGE(""https://docs.google.com/spreadsheets/d/1xsp01RMmkav9iTy39Zaj_7tE9677EGlOJ14KU9TZn7I"", ""2018-2025!H252"")"),232.883656) -> 232.88366 | E410: =IFERROR(__xludf.DUMMYFUNCTION("C410*IMPORTRANGE(""https://docs.google.com/spreadsheets/d/1xsp01RMmkav9iTy39Zaj_7tE9677EGlOJ14KU9TZn7I"", ""2018-2025!T252"")"),205.92834000000002) -> 205.92834 | F410: =IFERROR(__xludf.DUMMYFUNCTION("C410*IMPORTRANGE(""https://docs.google.com/spreadsheets/d/1xsp01RMmkav9iTy39Zaj_7tE9677EGlOJ14KU9TZn7I"", ""2018-2025!AC252"")"),30024.8776) -> 30024.878 | G410: Capital IQ
...

Sheet Quaterly
A1: Month | B1: Number | C1: Value
C2: in bil. USD | D2: in bil. EUR | E2: in bil. GBP | F2: in bil. YEN
A3: 1stQuarter 1985 | B3: 625 | C3: 67.62 | D3: 96.88 | E3: 58.99 | F3: 17301 | G3: Thomson Financial
A4: 2ndQuarter 1985 | B4: 631 | C4: 108.27 | D4: 150.01 | E4: 88 | F4: 26535.65 | G4: Thomson Financial
A5: 3rdQuarter 1985 | B5: 599 | C5: 66.72 | D5: 85.5 | E5: 49.09 | F5: 15360.48 | G5: Thomson Financial
A6: 4thQuarter 1985 | B6: 821 | C6: 104.67 | D6: 124.08 | E6: 73.57 | F6: 20899.57 | G6: Thomson Financial
A7: 1stQuarter 1986 | B7: 737 | C7: 78.11 | D7: 84.62 | E7: 54 | F7: 13912.26 | G7: Thomson Financial
A8: 2ndQuarter 1986 | B8: 927 | C8: 98.19 | D8: 102.9 | E8: 65.49 | F8: 16272.58 | G8: Thomson Financial
A9: 3rdQuarter 1986 | B9: 923 | C9: 98.66 | D9: 99.54 | E9: 66.75 | F9: 15403.28 | G9: Thomson Financial
A10: 4thQuarter 1986 | B10: 1642 | C10: 159.78 | D10: 154.65 | E10: 110.85 | F10: 25444.33 | G10: Thomson Financial
A11: 1stQuarter 1987 | B11: 1163 | C11: 103.59 | D11: 92.35 | E11: 66.99 | F11: 15374.08 | G11: Thomson Financial
A12: 2ndQuarter 1987 | B12: 1207 | C12: 131.98 | D12: 115.54 | E12: 81.53 | F12: 18794.71 | G12: Thomson Financial
A13: 3rdQuarter 1987 | B13: 1209 | C13: 138.7 | D13: 123.18 | E13: 85.98 | F13: 19936.45 | G13: Thomson Financial
A14: 4thQuarter 1987 | B14: 1701 | C14: 131.68 | D14: 110.13 | E14: 76.39 | F14: 17502.75 | G14: Thomson Financial
... A134: 4thQuarter 2017 | B134: 13765 | C134: 1161.98 | D134: 991.52 | E134: 877.39 | F134: 130703.49 | G134: Thomson Financial
A136: 1stQuarter 2018 | B136: =SUM(Monthly!B400:B402) -> 14492 | C136: =SUM(Monthly!C400:C402) -> 1040.6 | D136: =SUM(Monthly!D400:D402) -> 846.54347 | E136: =SUM(Monthly!E400:E402) -> 689.84702 | F136: =SUM(Monthly!F400:F402) -> 93349.185 | G136: Capital IQ
A137: 2ndQuarter 2018 | B137: =SUM(Monthly!B403:B405) -> 13634 | C137: =SUM(Monthly!C403:C405) -> 1258.42 | D137: =SUM(Monthly!D403:D405) -> 1052.9788 | E137: =SUM(Monthly!E403:E405) -> 921.28332 | F137: =SUM(Monthly!F403:F405) -> 136919.46 | G137: Capital IQ
A138: 3rdQuarter 2018 | B138: =SUM(Monthly!B406:B408) -> 13551 | C138: =SUM(Monthly!C406:C408) -> 806.5 | D138: =SUM(Monthly!D406:D408) -> 693.41641 | E138: =SUM(Monthly!E406:E408) -> 586.73065 | F138: =SUM(Monthly!F406:F408) -> 78550.331 | G138: Capital IQ
A139: 4thQuarter 2018 | B139: =SUM(Monthly!B409:B411) -> 14705 | C139: =SUM(Monthly!C409:C411) -> 833.75293 | D139: =SUM(Monthly!D409:D411) -> 729.63433 | E139: =SUM(Monthly!E409:E411) -> 647.38408 | F139: =SUM(Monthly!F409:F411) -> 94067.76 | G139: Capital IQ
A141: 1stQuarter 2019 | B141: =SUM(Monthly!B413:B415) -> 13556 | C141: =SUM(Monthly!C413:C415) -> 973.7798 | D141: =SUM(Monthly!D413:D415) -> 857.16059 | E141: =SUM(Monthly!E413:E415) -> 747.92044 | F141: =SUM(Monthly!F413:F415) -> 107363.46 | G141: Capital IQ
A142: 2ndQuarter 2019 | B142: =SUM(Monthly!B416:B418) -> 12976 | C142: =SUM(Monthly!C416:C418) -> 1143.6082 | D142: =SUM(Monthly!D416:D418) -> 1016.8497 | E142: =SUM(Monthly!E416:E418) -> 890.28907 | F142: =SUM(Monthly!F416:F418) -> 125476.4 | G142: Capital IQ
A143: 3rdQuarter 2019 | B143: =SUM(Monthly!B419:B421) -> 13088 | C143: =SUM(Monthly!C419:C421) -> 753.4066 | D143: =SUM(Monthly!D419:D421) -> 677.68244 | E143: =SUM(Monthly!E419:E421) -> 611.1021 | F143: =SUM(Monthly!F419:F421) -> 80852.869 | G143: Capital IQ
A144: 4thQuarter 2019 | B144: =SUM(Monthly!B422:B424) -> 13974 | C144: =SUM(Monthly!C422:C424) -> 1023.1183 | D144: =SUM(Monthly!D422:D424) -> 925.19887 | E144: =SUM(Monthly!E422:E424) -> 791.40962 | F144: =SUM(Monthly!F422:F424) -> 111428.67 | G144: Capital IQ
A146: 1stQuarter 2020 | B146: =SUM(Monthly!B426:B428) -> 12289 | C146: =SUM(Monthly!C426:C428) -> 657.9937 | D146: =SUM(Monthly!D426:D428) -> 596.62705 | E146: =SUM(Monthly!E426:E428) -> 512.88871 | F146: =SUM(Monthly!F426:F428) -> 71683.361 | G146: Capital IQ
A147: 2ndQuarter 2020 | B147: =SUM(Monthly!B429:B431) -> 8797 | C147: =SUM(Monthly!C429:C431) -> 335.0657 | D147: =SUM(Monthly!D429:D431) -> 302.80509 | E147: =SUM(Monthly!E429:E431) -> 269.37972 | F147: =SUM(Monthly!F429:F431) -> 35998.789 | G147: Capital IQ
A148: 3rdQuarter 2020 | B148: =SUM(Monthly!B432:B434) -> 11494 | C148: =SUM(Monthly!C432:C434) -> 984.0268 | D148: =SUM(Monthly!D432:D434) -> 840.02304 | E148: =SUM(Monthly!E432:E434) -> 763.59539 | F148: =SUM(Monthly!F432:F434) -> 104465.87 | G148: Capital IQ
A149: 4thQuarter 2020 | B149: =SUM(Monthly!B435:B437) -> 14727 | C149: =SUM(Monthly!C435:C437) -> 1291.408 | D149: =SUM(Monthly!D435:D437) -> 1082.664 | E149: =SUM(Monthly!E435:E437) -> 978.14997 | F149: =SUM(Monthly!F435:F437) -> 134981.22 | G149: Capital IQ
A151: 1stQuarter 2021 | B151: =SUM(Monthly!B439:B441) -> 14299 | C151: =SUM(Monthly!C439:C441) -> 1240.7265 | D151: =SUM(Monthly!D439:D441) -> 1029.275 | E151: =SUM(Monthly!E439:E441) -> 898.38969 | F151: =SUM(Monthly!F439:F441) -> 131778.08 | G151: Capital IQ
A152: 2ndQuarter 2021 | B152: =SUM(Monthly!B442:B444) -> 14399 | C152: =SUM(Monthly!C442:C444) -> 1399.0162 | D152: =SUM(Monthly!D442:D444) -> 1158.1352 | E152: =SUM(Monthly!E442:E444) -> 998.49546 | F152: =SUM(Monthly!F442:F444) -> 153008.56 | G152: Capital IQ
A153: 3rdQuarter 2021 | B153: =SUM(Monthly!B445:B447) -> 14067 | C153: =SUM(Monthly!C445:C447) -> 1371.9977 | D153: =SUM(Monthly!D445:D447) -> 1163.2458 | E153: =SUM(Monthly!E445:E447) -> 993.79465 | F153: =SUM(Monthly!F445:F447) -> 150921.33 | G153: Capital IQ
A154: 4thQuarter 2021 | B154: =SUM(Monthly!B448:B450) -> 15543 | C154: =SUM(Monthly!C448:C450) -> 1223.9072 | D154: =SUM(Monthly!D448:D450) -> 1071.8714 | E154: =SUM(Monthly!E448:E450) -> 911.36559 | F154: =SUM(Monthly!F448:F450) -> 139298.99 | G154: Capital IQ
A156: 1stQuarter 2022 | B156: =SUM(Monthly!B452:B454) -> 13930 | C156: =SUM(Monthly!C452:C454) -> 956.9373 | D156: =SUM(Monthly!D452:D454) -> 851.78676 | E156: =SUM(Monthly!E452:E454) -> 712.72296 | F156: =SUM(Monthly!F452:F454) -> 111000.83 | G156: Capital IQ
A157: 2ndQuarter 2022 | B157: =SUM(Monthly!B455:B457) -> 12393 | C157: =SUM(Monthly!C455:C457) -> 1083.2079 | D157: =SUM(Monthly!D455:D457) -> 1016.6142 | E157: =SUM(Monthly!E455:E457) -> 856.57045 | F157: =SUM(Monthly!F455:F457) -> 139812.41 | G157: Capital IQ
A158: 3rdQuarter 2022 | B158: =SUM(Monthly!B458:B460) -> 11971 | C158: =SUM(Monthly!C458:C460) -> 636.5619 | D158: =SUM(Monthly!D458:D460) -> 630.48932 | E158: =SUM(Monthly!E458:E460) -> 538.49282 | F158: =SUM(Monthly!F458:F460) -> 88080.86 | G158: Capital IQ
A159: 4thQuarter 2022 | B159: =SUM(Monthly!B461:B463) -> 12469 | C159: =SUM(Monthly!C461:C463) -> 707.0867 | D159: =SUM(Monthly!D461:D463) -> 689.40564 | E159: =SUM(Monthly!E461:E463) -> 600.75505 | F159: =SUM(Monthly!F461:F463) -> 99578.21 | G159: Capital IQ
A161: 1stQuarter2023 | B161: =SUM(Monthly!B465:B467) -> 11269 | C161: =SUM(Monthly!C465:C467) -> 600.8485 | D161: =SUM(Monthly!D465:D467) -> 560.06939 | E161: =SUM(Monthly!E465:E467) -> 495.14718 | F161: =SUM(Monthly!F465:F467) -> 79528.373 | G161: Capital IQ
A162: 2ndQuarter2023 | B162: =SUM(Monthly!B468:B470) -> 10496 | C162: =SUM(Monthly!C468:C470) -> 652.2264 | D162: =SUM(Monthly!D468:D470) -> 598.73245 | E162: =SUM(Monthly!E468:E470) -> 521.21287 | F162: =SUM(Monthly!F468:F470) -> 84087.401 | G162: Capital IQ
A163: 3rdQuarter2023 | B163: =SUM(Monthly!B471:B473) -> 9380 | C163: =SUM(Monthly!C471:C473) -> 565.14 | D163: =SUM(Monthly!D471:D473) -> 520.10148 | E163: =SUM(Monthly!E471:E473) -> 447.14375 | F163: =SUM(Monthly!F471:F473) -> 81917.843 | G163: Capital IQ
A164: 4thQuarter2023 | B164: =SUM(Monthly!B474:B476) -> 8458 | C164: =SUM(Monthly!C474:C476) -> 676.8422 | D164: =SUM(Monthly!D474:D476) -> 629.85161 | E164: =SUM(Monthly!E474:E476) -> 546.44612 | F164: =SUM(Monthly!F474:F476) -> 100031.77 | G164: Capital IQ
A166: 1stQuarter2024 | B166: =SUM(Monthly!B470:B472) -> 9840 | C166: =SUM(Monthly!C470:C472) -> 566.9724 | D166: =SUM(Monthly!D470:D472) -> 519.06581 | E166: =SUM(Monthly!E470:E472) -> 445.52281 | F166: =SUM(Monthly!F470:F472) -> 80629.563 | G166: Capital IQ
...
